Workbook

Sheet Index
A1: MIRAGE data inventory: every dataset, sample, model, test set and result the project uses
A2: Regenerate with: python backend/scripts/export_data_workbook.py. Cells over 2,000 characters are cut; the source file holds the full value.
A4: sheet | B4: what it holds | C4: source in the codebase | D4: rows
A5: Models | B5: Every pretrained detector: purpose, source repo, published accuracy, threshold and fusion weight | C5: app/witnesses/pretrained.py | D5: =MAX(COUNTA('Models'!A:A)-1,0)
A6: Local model files | B6: Trained or fitted artefacts stored on this machine | C6: backend/models_store/ | D6: =MAX(COUNTA('Local model files'!A:A)-1,0)
A7: External datasets | B7: Public datasets sampled for the field test (fetched with scripts/field_data.py fetch) | C7: scripts/field_data.py | D7: =MAX(COUNTA('External datasets'!A:A)-1,0)
A8: Field test files | B8: Every file in the field-test corpus (downloaded and generated) | C8: backend/var/fieldtest/ | D8: =MAX(COUNTA('Field test files'!A:A)-1,0)
A9: Field test generation | B9: Inputs used to generate synthetic field-test media | C9: scripts/field_data.py | D9: =MAX(COUNTA('Field test generation'!A:A)-1,0)
A10: Demo samples | B10: Built-in sample evidence used by scenarios, the copilot and Live Shield | C10: backend/var/samples/ | D10: =MAX(COUNTA('Demo samples'!A:A)-1,0)
A11: Scenarios | B11: Demo scenarios A–I with expected verdicts | C11: app/samples.py | D11: =MAX(COUNTA('Scenarios'!A:A)-1,0)
A12: Spoken scripts | B12: Scripts the sample voice notes and video were generated from | C12: app/samples.py | D12: =MAX(COUNTA('Spoken scripts'!A:A)-1,0)
A13: Live Shield demo | B13: Recorded per-window analysis replayed by the four Live Call Shield demo calls | C13: frontend/src/pages/app/liveDemo.ts | D13: =MAX(COUNTA('Live Shield demo'!A:A)-1,0)
A14: DB artifacts | B14: Every row of the 'artifacts' table (seed data, cases and activity) | C14: backend/var/mirage.db | D14: =MAX(COUNTA('DB artifacts'!A:A)-1,0)
A15: DB audit_log | B15: Every row of the 'audit_log' table (seed data, cases and activity) | C15: backend/var/mirage.db | D15: =MAX(COUNTA('DB audit_log'!A:A)-1,0)
A16: DB beneficiaries | B16: Every row of the 'beneficiaries' table (seed data, cases and activity) | C16: backend/var/mirage.db | D16: =MAX(COUNTA('DB beneficiaries'!A:A)-1,0)
A17: DB cases | B17: Every row of the 'cases' table (seed data, cases and activity) | C17: backend/var/mirage.db | D17: =MAX(COUNTA('DB cases'!A:A)-1,0)
A18: DB drills | B18: Every row of the 'drills' table (seed data, cases and activity) | C18: backend/var/mirage.db | D18: =MAX(COUNTA('DB drills'!A:A)-1,0)
A19: DB findings | B19: Every row of the 'findings' table (seed data, cases and activity) | C19: backend/var/mirage.db | D19: =MAX(COUNTA('DB findings'!A:A)-1,0)
A20: DB organizations | B20: Every row of the 'organizations' table (seed data, cases and activity) | C20: backend/var/mirage.db | D20: =MAX(COUNTA('DB organizations'!A:A)-1,0)
A21: DB people | B21: Every row of the 'people' table (seed data, cases and activity) | C21: backend/var/mirage.db | D21: =MAX(COUNTA('DB people'!A:A)-1,0)
A22: DB personas | B22: Every row of the 'personas' table (seed data, cases and activity) | C22: backend/var/mirage.db | D22: =MAX(COUNTA('DB personas'!A:A)-1,0)
A23: DB request_logs | B23: Every row of the 'request_logs' table (seed data, cases and activity) | C23: backend/var/mirage.db | D23: =MAX(COUNTA('DB request_logs'!A:A)-1,0)
A24: DB response_runs | B24: Every row of the 'response_runs' table (seed data, cases and activity) | C24: backend/var/mirage.db | D24: =MAX(COUNTA('DB response_runs'!A:A)-1,0)
A25: DB tribunal_messages | B25: Every row of the 'tribunal_messages' table (seed data, cases and activity) | C25: backend/var/mirage.db | D25: =MAX(COUNTA('DB tribunal_messages'!A:A)-1,0)
A26: DB verdicts | B26: Every row of the 'verdicts' table (seed data, cases and activity) | C26: backend/var/mirage.db | D26: =MAX(COUNTA('DB verdicts'!A:A)-1,0)
A27: DB verifications | B27: Every row of the 'verifications' table (seed data, cases and activity) | C27: backend/var/mirage.db | D27: =MAX(COUNTA('DB verifications'!A:A)-1,0)
A28: Text cases (tuned) | B28: Labelled scam / benign messages used to test the words witness (100) | C28: testing/text_cases.json | D28: =MAX(COUNTA('Text cases (tuned)'!A:A)-1,0)
A29: Text cases (held-out) | B29: Labelled scam / benign messages used to test the words witness (40) | C29: testing/text_cases_holdout.json | D29: =MAX(COUNTA('Text cases (held-out)'!A:A)-1,0)
A30: Copilot intents | B30: The 52 intents the copilot router is trained on | C30: app/assistant/catalog.py | D30: =MAX(COUNTA('Copilot intents'!A:A)-1,0)
A31: Copilot phrasings | B31: Every training phrasing for the copilot router | C31: app/assistant/catalog.py | D31: =MAX(COUNTA('Copilot phrasings'!A:A)-1,0)
A32: Copilot eval set | B32: Held-out questions scoring the router (never used for training) | C32: app/assistant/eval_set.py | D32: =MAX(COUNTA('Copilot eval set'!A:A)-1,0)
A33: Tactic lexicon | B33: Patterns the words witness uses to find pressure tactics (English regex and Indic words) | C33: app/witnesses/words.py | D33: =MAX(COUNTA('Tactic lexicon'!A:A)-1,0)
A34: Entity patterns | B34: Regexes for UPI IDs, accounts, URLs, phones and other identifiers | C34: app/witnesses/words.py | D34: =MAX(COUNTA('Entity patterns'!A:A)-1,0)
A35: Helplines | B35: Reporting channels shown in the emergency response card | C35: app/fusion/response.py | D35: =MAX(COUNTA('Helplines'!A:A)-1,0)
A36: Scam categories | B36: Categories a case is filed under | C36: app/fusion/response.py | D36: =MAX(COUNTA('Scam categories'!A:A)-1,0)
A37: Results benchmark | B37: Every value in benchmark.json, flattened (path = JSON key path) | C37: backend/models_store/benchmark.json | D37: =MAX(COUNTA('Results benchmark'!A:A)-1,0)
A38: Results metrics | B38: Every value in metrics.json, flattened (path = JSON key path) | C38: backend/models_store/metrics.json | D38: =MAX(COUNTA('Results metrics'!A:A)-1,0)
A39: Results fusion | B39: Every value in fusion.json, flattened (path = JSON key path) | C39: backend/models_store/fusion.json | D39: =MAX(COUNTA('Results fusion'!A:A)-1,0)
A40: Results copilot eval | B40: Every value in assistant_eval.json, flattened (path = JSON key path) | C40: backend/models_store/assistant_eval.json | D40: =MAX(COUNTA('Results copilot eval'!A:A)-1,0)
A41: Results field test | B41: Every value in field.json, flattened (path = JSON key path) | C41: testing/results/field.json | D41: =MAX(COUNTA('Results field test'!A:A)-1,0)
...

Sheet Models
A1: key | B1: name | C1: source (Hugging Face / file) | D1: witness | E1: role | F1: published accuracy | G1: threshold | H1: fusion weight
A2: df_arena | B2: DF_Arena_500M_V_1 | C2: Speech-Arena-2025/DF_Arena_500M_V_1 | D2: voice | E2: Synthetic-speech detection (primary) | F2: In-the-Wild EER 1.87% · 24-dataset mean EER 5.1% (Speech Anti-Spoofing Arena) | G2: 0.5 | H2: 0.5
A3: nii | B3: Wav2Vec2-Large-AntiDeepfake | C3: NII Wav2Vec2-Large-AntiDeepfake | D3: voice | E3: Synthetic-speech detection (primary) | F3: In-the-Wild EER 2.9% · Deepfake-Eval-2024 EER 30% (arXiv 2506.21090) | G3: 0.5 | H3: 0.2
A4: nii_mms | B4: MMS-300M-AntiDeepfake | C4: NII MMS-300M AntiDeepfake | D4: voice | E4: Synthetic-speech detection (multilingual, primary) | F4: In-the-Wild EER 4.8% · DeepVoice (RVC) EER 4.6% · MMS pretraining on 1,400 languages (arXiv 2506.21090) | G4: 0.3 | H4: 0.65
A5: nii_small | B5: Wav2Vec2-Small-AntiDeepfake | C5: NII Wav2Vec2-Small AntiDeepfake
A6: wavlm | B6: wavlm-base-plus-sv | C6: microsoft/wavlm-base-plus-sv | D6: voice | E6: Speaker verification (voiceprint) | F6: VoxCeleb1 EER 0.84% (model card)
A7: commfor | B7: commfor-model-384 | C7: Community Forensics ViT-S/384 | D7: provenance | E7: AI-generated image detection (primary) | F7: Trained on 4,803 generators (CVPR 2025) | G7: 0.01 | H7: 0.55
A8: swinv2 | B8: ai-image-detector-deploy | C8: haywoodsloan/ai-image-detector-deploy | D8: provenance | E8: AI-generated image detection | F8: SwinV2, modern diffusion generators (model card) | G8: 0.1 | H8: 0.45
A9: gend | B9: GenD_CLIP_L_14 | C9: GenD CLIP ViT-L/14 | D9: face | E9: Face-swap / reenactment detection (primary) | F9: Best mean cross-dataset AUROC over 14 benchmarks (WACV 2026) | G9: 0.75 | H9: 0.5
A10: gend_pe | B10: GenD_PE_L | C10: GenD Perception-Encoder L | D10: face | E10: Face-swap / reenactment detection (primary) | F10: GenD with Meta Perception Encoder backbone (WACV 2026) | G10: 0.75 | H10: 0.5
A11: clip | B11: clip-vit-large-patch14 | C11: openai/clip-vit-large-patch14
A12: phishing | B12: phishing-email-detection-distilbert_v2.4.1 | C12: cybersectony/phishing-email-detection-distilbert | D12: words | E12: Phishing / scam message classifier | F12: English emails and URLs (model card)
A13: nli | B13: mDeBERTa-v3-base-xnli-multilingual-nli-2mil7 | C13: MoritzLaurer/mDeBERTa-v3-base-xnli-multilingual-nli-2mil7 | D13: words | E13: Multilingual zero-shot intent | F13: XNLI 100 languages (model card)
A14: yunet | B14: yunet | C14: OpenCV YuNet | D14: face | E14: Face localisation | F14: WIDER Face (OpenCV Zoo)
A15: syncnet | B15: syncnet | C15: SyncNet v2 (VGG, Chung & Zisserman) | D15: face | E15: Audio-visual lip-sync | F15: LRS2 / VoxCeleb lip-sync (ACCV 2016 workshop)
A16: minilm | B16: paraphrase-multilingual-MiniLM-L12-v2 | C16: sentence-transformers/paraphrase-multilingual-MiniLM-L12-v2 | D16: casebook | E16: Dense retrieval (semantic search) | F16: 50+ languages, paraphrase mining (model card)

Sheet Local model files
A1: file | B1: size (KB)
A2: assistant_eval.json | B2: 2.8
A3: assistant_router.joblib | B3: 12655
A4: benchmark.json | B4: 67.8
A5: fusion.json | B5: 0.1
A6: image_clf.joblib | B6: 1335.8
A7: metrics.json | B7: 1.8
A8: request_anomaly.joblib | B8: 1612
A9: spk_background.npz | B9: 0.7
A10: voice_clf.joblib | B10: 1298
A11: words_clf.joblib | B11: 1618.1

Sheet External datasets
A1: name | B1: dataset | C1: config | D1: split | E1: rows in split | F1: sampled | G1: label
A2: hemg | B2: Hemg/Deepfake-Audio-Dataset | C2: default | D2: train | E2: 100 | F2: 50 | G2: real + fake speech
A3: ljspeech | B3: DynamicSuperb/SpeechDetection_LJSpeech | C3: default | D3: test | E3: 200 | F3: 30 | G3: real + fake speech
A4: indic_hindi | B4: SPRINGLab/IndicTTS-Hindi | C4: default | D4: train | E4: 11825 | F4: 30 | G4: real Hindi speech
A5: google_tamil | B5: ylacombe/google-tamil | C5: female | D5: train | E5: 2335 | F5: 20 | G5: real Tamil speech
A6: google_tamil_m | B6: ylacombe/google-tamil | C6: male | D6: train | E6: 2000 | F6: 20 | G6: real Tamil speech
A7: librispeech | B7: openslr/librispeech_asr | C7: all | D7: test.clean | E7: 2620 | F7: 40 | G7: real English speech
A8: flickr | B8: nlphuji/flickr30k | C8: TEST | D8: test | E8: 31014 | F8: 40 | G8: real photographs

Sheet Field test files
A1: path | B1: folder | C1: size (KB)
A2: audio/edge/chords_music.wav | B2: audio/edge | C2: 187.5
A3: audio/edge/silence_6s.wav | B3: audio/edge | C3: 187.5
A4: audio/edge/street_noise.wav | B4: audio/edge | C4: 187.5
A5: audio/edge/tone_440hz.wav | B5: audio/edge | C5: 187.5
A6: audio/edge/white_noise.wav | B6: audio/edge | C6: 187.5
A7: audio/fake/edge_multilang/bn-IN-TanishaaNeural.wav | B7: audio/fake/edge_multilang | C7: 198
A8: audio/fake/edge_multilang/en-GB-SoniaNeural.wav | B8: audio/fake/edge_multilang | C8: 168.8
A9: audio/fake/edge_multilang/en-IN-NeerjaNeural.wav | B9: audio/fake/edge_multilang | C9: 252
A10: audio/fake/edge_multilang/en-IN-PrabhatNeural.wav | B10: audio/fake/edge_multilang | C10: 237
A11: audio/fake/edge_multilang/en-US-GuyNeural.wav | B11: audio/fake/edge_multilang | C11: 231.8
A12: audio/fake/edge_multilang/gu-IN-NiranjanNeural.wav | B12: audio/fake/edge_multilang | C12: 273
A13: audio/fake/edge_multilang/hi-IN-MadhurNeural.wav | B13: audio/fake/edge_multilang | C13: 225
... A633: image/real_laundered/flickr_023__social.jpg | B633: image/real_laundered | C633: 49.1

Sheet Field test generation
A1: kind | B1: key | C1: value
A2: edge-tts voice | B2: en-IN-NeerjaNeural | C2: ["en-IN", "Hi, this is Neha from the accounts team. Please share the updated invoice before the meeting tomorrow."]
A3: edge-tts voice | B3: en-IN-PrabhatNeural | C3: ["en-IN", "Good afternoon. I'm calling about the quarterly review; the slides are in the shared folder."]
A4: edge-tts voice | B4: hi-IN-SwaraNeural | C4: ["hi-IN", "नमस्ते, मैं बैंक से बोल रही हूँ। आपका खाता सुरक्षित है, कृपया अपना पता अपडेट कर लीजिए।"]
A5: edge-tts voice | B5: hi-IN-MadhurNeural | C5: ["hi-IN", "पापा, मैं ठीक हूँ, बस आज कॉलेज में देर हो जाएगी। रात को फ़ोन करता हूँ।"]
A6: edge-tts voice | B6: ta-IN-PallaviNeural | C6: ["ta-IN", "வணக்கம், நான் உங்கள் வங்கியிலிருந்து பேசுகிறேன். உங்கள் கணக்கு விவரங்களை சரிபார்க்க வேண்டும்."]
A7: edge-tts voice | B7: te-IN-MohanNeural | C7: ["te-IN", "నమస్కారం, నేను ఆఫీసు నుండి మాట్లాడుతున్నాను. రేపటి సమావేశం పది గంటలకు ఉంటుంది."]
A8: edge-tts voice | B8: mr-IN-AarohiNeural | C8: ["mr-IN", "नमस्कार, मी तुमच्या मुलाच्या शाळेतून बोलत आहे. उद्या पालक सभा आहे."]
A9: edge-tts voice | B9: bn-IN-TanishaaNeural | C9: ["bn-IN", "নমস্কার, আমি ব্যাংক থেকে বলছি। আপনার কার্ডের তথ্য যাচাই করতে হবে।"]
A10: edge-tts voice | B10: gu-IN-NiranjanNeural | C10: ["gu-IN", "નમસ્તે, હું તમારી કંપનીના એચઆર વિભાગમાંથી બોલું છું. પગાર સ્લિપ મોકલી દીધી છે."]
A11: edge-tts voice | B11: en-US-GuyNeural | C11: ["en-US", "Hey, it's Mark from IT. We're rolling out a new VPN client this afternoon, nothing for you to do."]
A12: edge-tts voice | B12: en-GB-SoniaNeural | C12: ["en-GB", "Hello, this is the clinic confirming your appointment on Thursday at half past two."]
... A23: spoken script | B23: ta_benign | C23: ["ta-IN-PallaviNeural", "வணக்கம், நாளை காலை பத்து மணிக்கு கூட்டம் நடைபெறும். அனைவரும் வர வேண்டும்.", false]
A24: SAPI voice | B24: 0 | C24: Microsoft David Desktop
A25: SAPI voice | B25: 1 | C25: Microsoft Zira Desktop
A26: SAPI voice | B26: 2 | C26: Microsoft Heera Desktop
A27: SAPI voice | B27: 3 | C27: Microsoft Ravi Desktop
A28: SAPI text | B28: 0 | C28: Hello, this is your manager. Please process the vendor payment today and confirm by email.
A29: SAPI text | B29: 1 | C29: Your parcel is held at customs. Call this number to pay the clearance fee.
A30: SD-Turbo prompt | B30: 0 | C30: passport-style photo of an Indian man in his forties, plain background, realistic
A31: SD-Turbo prompt | B31: 1 | C31: candid photo of an Indian woman in a saree at a railway station, natural light
A32: SD-Turbo prompt | B32: 2 | C32: corporate headshot of a smiling executive in a blue suit, office background
A33: SD-Turbo prompt | B33: 3 | C33: an aadhaar-style identity card lying on a wooden table, photo
A34: SD-Turbo prompt | B34: 4 | C34: a bank cheque on a desk next to a pen, realistic photo
A35: SD-Turbo prompt | B35: 5 | C35: police officer in khaki uniform sitting at a desk, documentary photo
... A52: audio laundering | B52: 5 | C52: noise

Sheet Demo samples
A1: file | B1: size (KB) | C1: sha256
A2: .v5 | B2: 0 | C2: 2689367b205c16ce32ed4200942b8b8b1e262dfc70d9bc9fbc77c49699a4f1df
A3: .v6 | B3: 0 | C3: 2689367b205c16ce32ed4200942b8b8b1e262dfc70d9bc9fbc77c49699a4f1df
A4: cbi_notice.png | B4: 133 | C4: 81c17486b868f3d109e3e4159ad99dc96b03f8f4ee775e81c283ec0caf97c7f5
A5: ceo_meeting.mp4 | B5: 185.5 | C5: dcd6e1b3ce071839949027861d0b90307789c4195fd7679ea6faea24601214e6
A6: cfo_voice_note.wav | B6: 517.9 | C6: 0c6356b156fe3da29f708117352f28de11c438d0cdb8244ab289e7c8728114d2
A7: controller_voice.wav | B7: 218.8 | C7: 6d3028c25ad82112b875e63617be77b57b8b5905dba20e4fea21637999ea2a0e
A8: it_helpdesk.wav | B8: 343.9 | C8: fba1753c8ba9b178f7aa118c0f2625ee3adb89d4d03220b490e41ee78cb61997
A9: papa_voice_note.wav | B9: 350.8 | C9: 8ee650801c14eee68e4b6c098d232806785b31a005cd15483c392f5942151589
A10: short_clip.wav | B10: 46.9 | C10: 235ec47d5168f87a3b610c815c19b49b10e9da6260dfe146e31fcdc0d6519676
A11: townhall_avatar.wav | B11: 235.4 | C11: d6d00889494c5da15299d125fab1c2c2e2dae632a18541cc8ab299cfa623810b
A12: vendor_headshot.png | B12: 233.2 | C12: ccc1c417982603ef80acd77d687e91514a29e8676180703d0490ff6ca035bf5c
A13: vendor_invoice.eml | B13: 0.9 | C13: 3cbeb4efd93349e3f4dc6c1fb106b5232c04986143dba73874e23edfee5e39bc

Sheet Scenarios
A1: key | B1: code | C1: title | D1: story | E1: claimed_sender | F1: channel | G1: sender_contact | H1: message | I1: files | J1: expected | K1: received_hour | L1: tags | M1: hint
A2: cfo_wire | B2: A | C2: CFO voice note: urgent wire | D2: A cloned CFO voice note on WhatsApp asks Accounts Payable to wire ₹48.5 lakh to a new vendor before 4 PM. | E2: Rajesh Mehta (CFO) | F2: whatsapp | G2: +91 70451 88213 | H2: Hi, it's Rajesh. I'm in a board meeting, can't take calls. Please process ₹48,50,000 to the new vendor account 918273645501 IFSC HDFC0001234 before 4 PM — very urgent. Keep this between us, bhai, audit wale ko abhi mat batana. | I2: ["cfo_voice_note.wav"] | J2: HIGH | K2: 15 | L2: ["voice", "BEC", "Hinglish"]
A3: video_meeting | B3: B | C3: Deepfake video meeting | D3: A recorded 'all-hands' clip with the CEO asking finance to move funds for a confidential acquisition. | E3: Ashok Raman (CEO) | F3: video | H3: As discussed on the call, transfer ₹3.2 crore to the escrow account 50100776655441 today. This is confidential until the acquisition is announced. Do not discuss with anyone in finance. | I3: ["ceo_meeting.mp4"] | J3: HIGH | K3: 18 | L3: ["video", "Arup pattern"]
A4: it_otp | B4: C | C4: IT help-desk OTP reset | D4: A short, heavily compressed voice note from 'IT support' asks for the OTP to finish a password reset. | E4: IT helpdesk | F4: phone | G4: +91 88002 31109 | H4: IT team se bol raha hoon, aapka account reset ho raha hai. Jo OTP aaya hai woh bata do jaldi, 10 minute mein lock ho jayega. | I4: ["it_helpdesk.wav"] | J4: HIGH | K4: 21 | L4: ["credential", "Hinglish"]
A5: real_voice_fraud | B5: D | C5: Genuine voice, fraudulent request | D5: The Financial Controller's real voice, but the message asks to pay a never-seen account. The media is fine; the request is not. | E5: Priya Nair | F5: teams | H5: Hi Kavita, please pay ₹14,00,000 to this new account 778899001122 for the Orbit settlement today. Thanks. | I5: ["controller_voice.wav"] | J5: HIGH | K5: 11 | L5: ["context beats detection"]
A6: harmless_avatar | B6: E | C6: Labelled AI avatar, harmless | D6: An AI-generated presenter voice announces the Friday townhall. Synthetic, but it asks for nothing. | F6: email | H6: Join us for the quarterly townhall on Friday at 4 PM in the main auditorium. Snacks will be served! | I6: ["townhall_avatar.wav"] | J6: LOW | K6: 10 | L6: ["no false alarm"]
A7: papa_emergency | B7: F | C7: 'Papa' emergency voice note | D7: A Hinglish voice note in a cloned father's voice from an unknown number asks for money on UPI right now. | E7: Papa | F7: whatsapp | G7: +91 73040 99812 | H7: Beta main hoon, accident ho gaya hai, phone toot gaya. Paise abhi bhejo family.help@ibl pe, ₹75,000, kisi ko mat batana please. | I7: ["papa_voice_note.wav"] | J7: HIGH | K7: 22 | L7: ["family", "Hinglish", "UPI"]
A8: digital_arrest | B8: G | C8: 'CBI officer' digital arrest | D8: A screenshot of a forged 'CBI notice' and a message demanding a verification deposit on a video call. | E8: Inspector Sharma, CBI Cyber Cell | F8: video | G8: +91 90011 22334 | H8: This is Inspector Sharma from CBI Cyber Cell. A parcel in your name contains illegal items. You are under digital arrest. Do not disconnect or inform anyone. Transfer ₹2,40,000 to safeacct.rbi@oksbi for verification. | I8: ["cbi_notice.png"] | J8: HIGH | K8: 13 | L8: ["image", "digital arrest"] | M8: digital_arrest
A9: vendor_headshot | B9: H | C9: Vendor BEC email with AI headshot | D9: A 'new account manager' at a known vendor emails changed bank details with an AI-generated headshot. The original .eml carries the headers. | E9: Orbit Supplies billing | F9: email | I9: ["vendor_invoice.eml", "vendor_headshot.png"] | J9: HIGH | K9: 16 | L9: ["image", "email", "BEC"]
A10: too_little | B10: I | C10: Too little evidence | D10: A 1.5-second clip with no message and no sender. MIRAGE should say it cannot tell. | F10: unknown | I10: ["short_clip.wav"] | J10: INCONCLUSIVE | K10: 12 | L10: ["honest uncertainty"]

Sheet Spoken scripts
A1: key | B1: script | C1: voice
A2: cfo | B2: Hi, it's Rajesh. I'm in a board meeting and can't take calls. Please process forty eight lakh fifty thousand rupees to the new vendor account before 4 PM. Very urgent. Keep this between us, audit wale ko abhi mat batana. | C2: Rishi
A3: it | B3: IT team se bol raha hoon. Aapka account reset ho raha hai. Jo OTP aaya hai woh bata do jaldi, ten minute mein lock ho jayega. | C3: Rishi
A4: townhall | B4: Join us for the quarterly townhall on Friday at 4 PM in the main auditorium. Snacks will be served! | C4: Tara
A5: papa | B5: Beta main hoon, accident ho gaya hai, phone toot gaya. Paise abhi bhejo, seventy five thousand. Kisi ko mat batana please. | C5: Aman
A6: ceo | B6: As discussed on the call, transfer three point two crore to the escrow account today. This is confidential until the acquisition is announced. Do not discuss with anyone in finance. | C6: Aman

Sheet Live Shield demo
A1: call | B1: window | C1: start (s) | D1: synthetic voice | E1: transcript | F1: tactics | G1: request | H1: manipulation | I1: amount (INR)
A2: cfo_voice_note.wav | B2: 1 | C2: 0 | D2: 1 | E2: Hi, it's Rajesh. I'm in a | G2: none | H2: 0.432
A3: cfo_voice_note.wav | B3: 2 | C3: 3 | D3: 1 | E3: board meeting and can't take calls. | F3: authority, channel_switch | G3: none | H3: 0.762
A4: cfo_voice_note.wav | B4: 3 | C4: 6 | D4: 1 | E4: Please process 48,50,000 rupees to the | F4: authority, channel_switch | G4: payment | H4: 0.908 | I4: 4850000
A5: cfo_voice_note.wav | B5: 4 | C5: 9 | D5: 1 | E5: new vendor account before 4 PM. | F5: authority, channel_switch, urgency | G5: payment | H5: 0.948 | I5: 4850000
A6: cfo_voice_note.wav | B6: 5 | C6: 12 | D6: 1 | E6: Very urgent. Keep this between us, | F6: authority, channel_switch, secrecy, urgency | G6: payment | H6: 0.994 | I6: 4850000
A7: cfo_voice_note.wav | B7: 6 | C7: 15 | D7: 1 | E7: audit wale ko abhi mat batana. | F7: authority, bypass, channel_switch, secrecy, urgency | G7: payment | H7: 1 | I7: 4850000
A8: papa_voice_note.wav | B8: 1 | C8: 0 | D8: 1 | E8: Beta main hoon, accident ho | F8: fear | G8: none | H8: 0.805
A9: papa_voice_note.wav | B9: 2 | C9: 3 | D9: 1 | E9: gaya hai, phone toot gaya. | F9: channel_switch, fear | G9: none | H9: 0.866
A10: papa_voice_note.wav | B10: 3 | C10: 6 | D10: 1 | E10: Paise abhi bhejo, ₹75,000. | F10: channel_switch, fear, urgency | G10: payment | H10: 0.947 | I10: 75000
A11: papa_voice_note.wav | B11: 4 | C11: 9 | D11: 1 | E11: Kisi ko mat batana please. | F11: channel_switch, fear, secrecy, urgency | G11: payment | H11: 0.994 | I11: 75000
A12: it_helpdesk.wav | B12: 1 | C12: 0 | D12: 1 | E12: IT team se bol raha hoon. | F12: authority | G12: none | H12: 0.589
A13: it_helpdesk.wav | B13: 2 | C13: 3 | D13: 1 | E13: Aapka account reset ho raha hai. Jo | F13: authority | G13: none | H13: 0.873
A14: it_helpdesk.wav | B14: 3 | C14: 6 | D14: 1 | E14: OTP aaya hai woh bata do jaldi, | F14: authority, urgency | G14: credential | H14: 0.903
A15: it_helpdesk.wav | B15: 4 | C15: 9 | D15: 1 | E15: 10 minute mein lock ho jayega. | F15: authority, urgency | G15: credential | H15: 0.902
A16: townhall_avatar.wav | B16: 1 | C16: 0 | D16: 1 | E16: Join us for the quarterly townhall | G16: none | H16: 0.005
A17: townhall_avatar.wav | B17: 2 | C17: 3 | D17: 1 | E17: on Friday at 4 PM in the | G17: none | H17: 0.003
A18: townhall_avatar.wav | B18: 3 | C18: 6 | D18: 0.997 | E18: main auditorium. Snacks will be served! | G18: none | H18: 0.006

Sheet DB artifacts
A1: id | B1: case_id | C1: kind | D1: filename | E1: mime | F1: sha256 | G1: size_bytes | H1: storage_key | I1: duration_s | J1: meta_json
A2: 1 | B2: MRG-0458 | C2: audio | D2: cfo_voice_note.wav | E2: audio/wav | F2: 0c6356b156fe3da29f708117352f28de11c438d0cdb8244ab289e7c8728114d2 | G2: 530346 | H2: 0c/0c6356b156fe3da29f708117352f28de11c438d0cdb8244ab289e7c8728114d2.wav | I2: 16.57 | J2: {"transcript": "Voice call: confirming the Orbit change, please release the pending \u20b99,80,000 to 600112233445 urgently.", "asr": {"text": "Hi, it's Rajesh. I'm in a board meeting and can't take calls. Please process 48 .50 ,000 rupees to the new vendor account before 4PM very urgent. Keep this between us, AuditWale .co .ubi Matt Batina", "language": "en", "language_p": 1.0, "words": [{"w": "Hi,", "t0": 0.0, "t1": 0.34, "p": 0.77}, {"w": "it's", "t0": 0.68, "t1": 1.02, "p": 0.81}, {"w": "Rajesh.", "t0": 1.02, "t1": 1.34, "p": 0.87}, {"w": "I'm", "t0": 2.26, "t1": 2.64, "p": 0.98}, {"w": "in", "t0": 2.64, "t1": 2.68, "p": 0.98}, {"w": "a", "t0": 2.68, "t1": 2.78, "p": 0.92}, {"w": "board", "t0": 2.78, "t1": 2.98, "p": 0.91}, {"w": "meeting", "t0": 2.98, "t1": 3.3, "p": 1.0}, {"w": "and", "t0": 3.3, "t1": 3.56, "p": 1.0}, {"w": "can't", "t0": 3.56, "t1": 3.92, "p": 0.97}, {"w": "take", "t0": 3.92, "t1": 4.06, "p": 1.0}, {"w": "calls.", "t0": 4.06, "t1": 4.54, "p": 1.0}, {"w": "Please", "t0": 5.58, "t1": 5.8, "p": 0.96}, {"w": "process", "t0": 5.8, "t1": 6.28, "p": 0.96}, {"w": "48", "t0": 6.28, "t1": 6.84, "p": 0.98}, {"w": ".50", "t0": 6.84, "t1": 7.54, "p": 0.54}, {"w": ",000", "t0": 7.54, "t1": 8.08, "p": 0.71}, {"w": "rupees", "t0": 8.08, "t1": 8.42, "p": 0.81}, {"w": "to", "t0": 8.42, "t1": 8.7, "p": 1.0}, {"w": "the", "t0": 8.7, "t1": 8.82, "p": 0.99}, {"w": "new", "t0": 8.82, "t1": 8.98, "p": 0.8}, {"w": "vendor", "t0": 8.98, "t1": 9.24, "p": 0.92}, {"w": "account", "t0": 9.24, "t1": 9.6, "p": 1.0}, {"w": "before", "t0": 9.6, "t1": 9.96, "p": 0.99}, {"w": "4PM", "t0": 9.96, "t1": 10.68, "p": 0.64}, {"w": "very", "t0": 10.68, "t1": 11.1, "p": 0.62}, {"w": "urgent.", "t0": 11.1, "t1": 11.46, "p": 1.0}, {"w": "Keep", "t0": 12.28, "t1": 12.66, "p": 0.98}, {"w": "this", "t0": 12.66, "t1": 12.88, "p": 0.99}, {"w": "between", "t0": 12.88, "t1": 13.24, "p": 0.99}, {"w": "us,", "t0": 13.24, "t1": 13.54, "p": 1.0}, {"w": "AuditWale", "t0": 14.0, "t1": 14.46, "p": 0.5 …(truncated)
A3: 2 | B3: MRG-0459 | C3: video | D3: ceo_meeting.mp4 | E3: video/mp4 | F3: dcd6e1b3ce071839949027861d0b90307789c4195fd7679ea6faea24601214e6 | G3: 190002 | H3: dc/dcd6e1b3ce071839949027861d0b90307789c4195fd7679ea6faea24601214e6.mp4 | I3: 12.61 | J3: {"transcript": "Video meeting: the CEO and CFO ask to move \u20b948,50,000 to 600112233445 today for a confidential settlement. Do not discuss with anyone in finance.", "asr": {"text": "As discussed on the call, transfer 3 .2 crore to the escrow account today. This is confidential until the acquisition is announced. Do not discuss with anyone in finance.", "language": "en", "language_p": 1.0, "words": [{"w": "As", "t0": 0.0, "t1": 0.26, "p": 0.65}, {"w": "discussed", "t0": 0.26, "t1": 0.62, "p": 1.0}, {"w": "on", "t0": 0.62, "t1": 0.92, "p": 1.0}, {"w": "the", "t0": 0.92, "t1": 1.06, "p": 1.0}, {"w": "call,", "t0": 1.06, "t1": 1.32, "p": 0.99}, {"w": "transfer", "t0": 1.84, "t1": 2.3, "p": 0.94}, {"w": "3", "t0": 2.3, "t1": 2.76, "p": 0.93}, {"w": ".2", "t0": 2.76, "t1": 3.2, "p": 0.99}, {"w": "crore", "t0": 3.2, "t1": 3.5, "p": 0.77}, {"w": "to", "t0": 3.5, "t1": 3.68, "p": 1.0}, {"w": "the", "t0": 3.68, "t1": 3.84, "p": 0.99}, {"w": "escrow", "t0": 3.84, "t1": 4.26, "p": 0.85}, {"w": "account", "t0": 4.26, "t1": 4.54, "p": 0.99}, {"w": "today.", "t0": 4.54, "t1": 4.92, "p": 1.0}, {"w": "This", "t0": 5.48, "t1": 6.04, "p": 0.99}, {"w": "is", "t0": 6.04, "t1": 6.2, "p": 1.0}, {"w": "confidential", "t0": 6.2, "t1": 6.7, "p": 1.0}, {"w": "until", "t0": 6.7, "t1": 7.2, "p": 0.99}, {"w": "the", "t0": 7.2, "t1": 7.44, "p": 1.0}, {"w": "acquisition", "t0": 7.44, "t1": 7.9, "p": 1.0}, {"w": "is", "t0": 7.9, "t1": 8.22, "p": 1.0}, {"w": "announced.", "t0": 8.22, "t1": 8.74, "p": 1.0}, {"w": "Do", "t0": 9.52, "t1": 9.82, "p": 0.99}, {"w": "not", "t0": 9.82, "t1": 9.98, "p": 0.99}, {"w": "discuss", "t0": 9.98, "t1": 10.36, "p": 1.0}, {"w": "with", "t0": 10.36, "t1": 10.62, "p": 1.0}, {"w": "anyone", "t0": 10.62, "t1": 11.02, "p": 0.99}, {"w": "in", "t0": 11.02, "t1": 11.24, "p": 1.0}, {"w": "finance.", "t0": 11.24, "t1": 11.6, "p": 0.87}], "engine": "faster-whisper/base"}}
A4: 3 | B4: MRG-0461 | C4: audio | D4: cfo_voice_note.wav | E4: audio/wav | F4: 0c6356b156fe3da29f708117352f28de11c438d0cdb8244ab289e7c8728114d2 | G4: 530346 | H4: 0c/0c6356b156fe3da29f708117352f28de11c438d0cdb8244ab289e7c8728114d2.wav | I4: 16.57 | J4: {"asr": {"text": "Hi, it's Rajesh. I'm in a board meeting and can't take calls. Please process 48 .50 ,000 rupees to the new vendor account before 4PM very urgent. Keep this between us, AuditWale .co .ubi Matt Batina", "language": "en", "language_p": 1.0, "words": [{"w": "Hi,", "t0": 0.0, "t1": 0.34, "p": 0.77}, {"w": "it's", "t0": 0.68, "t1": 1.02, "p": 0.81}, {"w": "Rajesh.", "t0": 1.02, "t1": 1.34, "p": 0.87}, {"w": "I'm", "t0": 2.26, "t1": 2.64, "p": 0.98}, {"w": "in", "t0": 2.64, "t1": 2.68, "p": 0.98}, {"w": "a", "t0": 2.68, "t1": 2.78, "p": 0.92}, {"w": "board", "t0": 2.78, "t1": 2.98, "p": 0.91}, {"w": "meeting", "t0": 2.98, "t1": 3.3, "p": 1.0}, {"w": "and", "t0": 3.3, "t1": 3.56, "p": 1.0}, {"w": "can't", "t0": 3.56, "t1": 3.92, "p": 0.97}, {"w": "take", "t0": 3.92, "t1": 4.06, "p": 1.0}, {"w": "calls.", "t0": 4.06, "t1": 4.54, "p": 1.0}, {"w": "Please", "t0": 5.58, "t1": 5.8, "p": 0.96}, {"w": "process", "t0": 5.8, "t1": 6.28, "p": 0.96}, {"w": "48", "t0": 6.28, "t1": 6.84, "p": 0.98}, {"w": ".50", "t0": 6.84, "t1": 7.54, "p": 0.54}, {"w": ",000", "t0": 7.54, "t1": 8.08, "p": 0.71}, {"w": "rupees", "t0": 8.08, "t1": 8.42, "p": 0.81}, {"w": "to", "t0": 8.42, "t1": 8.7, "p": 1.0}, {"w": "the", "t0": 8.7, "t1": 8.82, "p": 0.99}, {"w": "new", "t0": 8.82, "t1": 8.98, "p": 0.8}, {"w": "vendor", "t0": 8.98, "t1": 9.24, "p": 0.92}, {"w": "account", "t0": 9.24, "t1": 9.6, "p": 1.0}, {"w": "before", "t0": 9.6, "t1": 9.96, "p": 0.99}, {"w": "4PM", "t0": 9.96, "t1": 10.68, "p": 0.64}, {"w": "very", "t0": 10.68, "t1": 11.1, "p": 0.62}, {"w": "urgent.", "t0": 11.1, "t1": 11.46, "p": 1.0}, {"w": "Keep", "t0": 12.28, "t1": 12.66, "p": 0.98}, {"w": "this", "t0": 12.66, "t1": 12.88, "p": 0.99}, {"w": "between", "t0": 12.88, "t1": 13.24, "p": 0.99}, {"w": "us,", "t0": 13.24, "t1": 13.54, "p": 1.0}, {"w": "AuditWale", "t0": 14.0, "t1": 14.46, "p": 0.57}, {"w": ".co", "t0": 14.46, "t1": 14.8, "p": 0.34}, {"w": ".ubi", "t0": 14.8, "t1": 15.1, "p": 0.33}, {"w": "Matt", "t0": 15 …(truncated)
A5: 4 | B5: MRG-0462 | C5: video | D5: ceo_meeting.mp4 | E5: video/mp4 | F5: dcd6e1b3ce071839949027861d0b90307789c4195fd7679ea6faea24601214e6 | G5: 190002 | H5: dc/dcd6e1b3ce071839949027861d0b90307789c4195fd7679ea6faea24601214e6.mp4 | I5: 12.61 | J5: {"asr": {"text": "As discussed on the call, transfer 3 .2 crore to the escrow account today. This is confidential until the acquisition is announced. Do not discuss with anyone in finance.", "language": "en", "language_p": 1.0, "words": [{"w": "As", "t0": 0.0, "t1": 0.26, "p": 0.65}, {"w": "discussed", "t0": 0.26, "t1": 0.62, "p": 1.0}, {"w": "on", "t0": 0.62, "t1": 0.92, "p": 1.0}, {"w": "the", "t0": 0.92, "t1": 1.06, "p": 1.0}, {"w": "call,", "t0": 1.06, "t1": 1.32, "p": 0.99}, {"w": "transfer", "t0": 1.84, "t1": 2.3, "p": 0.94}, {"w": "3", "t0": 2.3, "t1": 2.76, "p": 0.93}, {"w": ".2", "t0": 2.76, "t1": 3.2, "p": 0.99}, {"w": "crore", "t0": 3.2, "t1": 3.5, "p": 0.77}, {"w": "to", "t0": 3.5, "t1": 3.68, "p": 1.0}, {"w": "the", "t0": 3.68, "t1": 3.84, "p": 0.99}, {"w": "escrow", "t0": 3.84, "t1": 4.26, "p": 0.85}, {"w": "account", "t0": 4.26, "t1": 4.54, "p": 0.99}, {"w": "today.", "t0": 4.54, "t1": 4.92, "p": 1.0}, {"w": "This", "t0": 5.48, "t1": 6.04, "p": 0.99}, {"w": "is", "t0": 6.04, "t1": 6.2, "p": 1.0}, {"w": "confidential", "t0": 6.2, "t1": 6.7, "p": 1.0}, {"w": "until", "t0": 6.7, "t1": 7.2, "p": 0.99}, {"w": "the", "t0": 7.2, "t1": 7.44, "p": 1.0}, {"w": "acquisition", "t0": 7.44, "t1": 7.9, "p": 1.0}, {"w": "is", "t0": 7.9, "t1": 8.22, "p": 1.0}, {"w": "announced.", "t0": 8.22, "t1": 8.74, "p": 1.0}, {"w": "Do", "t0": 9.52, "t1": 9.82, "p": 0.99}, {"w": "not", "t0": 9.82, "t1": 9.98, "p": 0.99}, {"w": "discuss", "t0": 9.98, "t1": 10.36, "p": 1.0}, {"w": "with", "t0": 10.36, "t1": 10.62, "p": 1.0}, {"w": "anyone", "t0": 10.62, "t1": 11.02, "p": 0.99}, {"w": "in", "t0": 11.02, "t1": 11.24, "p": 1.0}, {"w": "finance.", "t0": 11.24, "t1": 11.6, "p": 0.87}], "engine": "faster-whisper/base"}}
A6: 5 | B6: MRG-0463 | C6: audio | D6: it_helpdesk.wav | E6: audio/wav | F6: fba1753c8ba9b178f7aa118c0f2625ee3adb89d4d03220b490e41ee78cb61997 | G6: 352134 | H6: fb/fba1753c8ba9b178f7aa118c0f2625ee3adb89d4d03220b490e41ee78cb61997.wav | I6: 11 | J6: {"asr": {"text": "IT Team SE Valra Hoon Opca Account Reset Ho Reha High Jo OTP AIO Highwell Bata Do Jaldi 10 Minute Main Lock Ho Jiega", "language": "en", "language_p": 1.0, "words": [{"w": "IT", "t0": 0.0, "t1": 0.38, "p": 0.62}, {"w": "Team", "t0": 0.38, "t1": 0.76, "p": 0.56}, {"w": "SE", "t0": 0.76, "t1": 1.02, "p": 0.48}, {"w": "Valra", "t0": 1.02, "t1": 1.46, "p": 0.38}, {"w": "Hoon", "t0": 1.46, "t1": 1.92, "p": 0.47}, {"w": "Opca", "t0": 2.64, "t1": 3.12, "p": 0.3}, {"w": "Account", "t0": 3.12, "t1": 3.44, "p": 0.53}, {"w": "Reset", "t0": 3.44, "t1": 3.88, "p": 0.84}, {"w": "Ho", "t0": 3.88, "t1": 4.06, "p": 0.38}, {"w": "Reha", "t0": 4.06, "t1": 4.36, "p": 0.38}, {"w": "High", "t0": 4.36, "t1": 4.76, "p": 0.17}, {"w": "Jo", "t0": 5.28, "t1": 5.66, "p": 0.24}, {"w": "OTP", "t0": 5.66, "t1": 6.08, "p": 0.75}, {"w": "AIO", "t0": 6.08, "t1": 6.58, "p": 0.24}, {"w": "Highwell", "t0": 6.58, "t1": 6.94, "p": 0.07}, {"w": "Bata", "t0": 6.94, "t1": 7.24, "p": 0.34}, {"w": "Do", "t0": 7.24, "t1": 7.44, "p": 0.21}, {"w": "Jaldi", "t0": 7.44, "t1": 7.96, "p": 0.56}, {"w": "10", "t0": 7.96, "t1": 8.6, "p": 0.52}, {"w": "Minute", "t0": 8.6, "t1": 8.8, "p": 0.59}, {"w": "Main", "t0": 8.8, "t1": 9.08, "p": 0.87}, {"w": "Lock", "t0": 9.08, "t1": 9.34, "p": 0.71}, {"w": "Ho", "t0": 9.34, "t1": 9.6, "p": 0.7}, {"w": "Jiega", "t0": 9.6, "t1": 10.1, "p": 0.56}], "engine": "faster-whisper/base"}}
A7: 6 | B7: MRG-0464 | C7: audio | D7: controller_voice.wav | E7: audio/wav | F7: 6d3028c25ad82112b875e63617be77b57b8b5905dba20e4fea21637999ea2a0e | G7: 224044 | H7: 6d/6d3028c25ad82112b875e63617be77b57b8b5905dba20e4fea21637999ea2a0e.wav | I7: 7 | J7: {}
A8: 7 | B8: MRG-0465 | C8: audio | D8: en_cfo_payment.wav | E8: audio/wav | F8: 9c2dc59996e0c43f7bc7eaf65d9d5326eedb9819ddecd62acb29b0cacf9516a4 | G8: 516140 | H8: 9c/9c2dc59996e0c43f7bc7eaf65d9d5326eedb9819ddecd62acb29b0cacf9516a4.wav | I8: 16.13 | J8: {"asr": {"text": "Hi, this is Rajesh, the CFO. I'm in a board meeting. Transfer 12 lakh rupees to the new vendor account today and keep it confidential. Don't call me, just do it before 4.", "language": "en", "language_p": 1.0, "words": [{"w": "Hi,", "t0": 0.0, "t1": 0.38, "p": 0.9}, {"w": "this", "t0": 0.7, "t1": 0.92, "p": 0.79}, {"w": "is", "t0": 0.92, "t1": 1.22, "p": 0.99}, {"w": "Rajesh,", "t0": 1.22, "t1": 1.64, "p": 0.97}, {"w": "the", "t0": 2.02, "t1": 2.12, "p": 0.97}, {"w": "CFO.", "t0": 2.12, "t1": 2.58, "p": 0.91}, {"w": "I'm", "t0": 3.38, "t1": 3.88, "p": 0.79}, {"w": "in", "t0": 3.88, "t1": 4.04, "p": 0.99}, {"w": "a", "t0": 4.04, "t1": 4.16, "p": 0.98}, {"w": "board", "t0": 4.16, "t1": 4.42, "p": 0.86}, {"w": "meeting.", "t0": 4.42, "t1": 4.92, "p": 1.0}, {"w": "Transfer", "t0": 5.82, "t1": 6.36, "p": 0.97}, {"w": "12", "t0": 6.36, "t1": 6.9, "p": 0.83}, {"w": "lakh", "t0": 6.9, "t1": 7.14, "p": 0.44}, {"w": "rupees", "t0": 7.14, "t1": 7.58, "p": 0.88}, {"w": "to", "t0": 7.58, "t1": 7.92, "p": 0.99}, {"w": "the", "t0": 7.92, "t1": 8.06, "p": 0.97}, {"w": "new", "t0": 8.06, "t1": 8.28, "p": 0.88}, {"w": "vendor", "t0": 8.28, "t1": 8.64, "p": 0.72}, {"w": "account", "t0": 8.64, "t1": 9.08, "p": 0.99}, {"w": "today", "t0": 9.08, "t1": 9.58, "p": 0.99}, {"w": "and", "t0": 9.58, "t1": 10.2, "p": 0.66}, {"w": "keep", "t0": 10.2, "t1": 10.46, "p": 1.0}, {"w": "it", "t0": 10.46, "t1": 10.7, "p": 1.0}, {"w": "confidential.", "t0": 10.7, "t1": 11.34, "p": 1.0}, {"w": "Don't", "t0": 12.26, "t1": 12.76, "p": 0.97}, {"w": "call", "t0": 12.76, "t1": 12.98, "p": 0.98}, {"w": "me,", "t0": 12.98, "t1": 13.28, "p": 0.99}, {"w": "just", "t0": 13.68, "t1": 13.86, "p": 0.95}, {"w": "do", "t0": 13.86, "t1": 14.22, "p": 1.0}, {"w": "it", "t0": 14.22, "t1": 14.44, "p": 1.0}, {"w": "before", "t0": 14.44, "t1": 14.78, "p": 0.99}, {"w": "4.", "t0": 14.78, "t1": 15.24, "p": 0.91}], "engine": "faster-whisper/base"}}
A9: 8 | B9: MRG-0466 | C9: audio | D9: hi_digital_arrest.wav | E9: audio/wav | F9: 199e85bffa3c9e5c809b3a12a4e6b87d8549803328e29a7edbfb76177670d5e8 | G9: 473900 | H9: 19/199e85bffa3c9e5c809b3a12a4e6b87d8549803328e29a7edbfb76177670d5e8.wav | I9: 14.81 | J9: {"asr": {"text": "I am speaking with CBI. Your name is Drugs parcel. Don't call anyone. Send two lakh rupees to the judge.", "language": "hi-Latn (Hinglish)", "language_p": 1.0, "words": [{"w": "I", "t0": 0.0, "t1": 0.42, "p": 0.68}, {"w": "am", "t0": 0.42, "t1": 0.42, "p": 0.79}, {"w": "speaking", "t0": 0.42, "t1": 0.42, "p": 0.69}, {"w": "with", "t0": 0.42, "t1": 0.42, "p": 0.29}, {"w": "CBI.", "t0": 0.42, "t1": 1.02, "p": 0.77}, {"w": "Your", "t0": 3.32, "t1": 3.94, "p": 0.23}, {"w": "name", "t0": 3.94, "t1": 4.3, "p": 0.95}, {"w": "is", "t0": 4.3, "t1": 4.64, "p": 0.66}, {"w": "Drugs", "t0": 4.64, "t1": 4.98, "p": 0.55}, {"w": "parcel.", "t0": 4.98, "t1": 5.6, "p": 0.32}, {"w": "Don't", "t0": 6.56, "t1": 7.78, "p": 0.81}, {"w": "call", "t0": 7.78, "t1": 7.78, "p": 0.42}, {"w": "anyone.", "t0": 7.78, "t1": 8.82, "p": 0.69}, {"w": "Send", "t0": 10.46, "t1": 11.7, "p": 0.01}, {"w": "two", "t0": 11.7, "t1": 12.06, "p": 0.58}, {"w": "lakh", "t0": 12.06, "t1": 12.4, "p": 0.52}, {"w": "rupees", "t0": 12.4, "t1": 12.78, "p": 0.33}, {"w": "to", "t0": 12.78, "t1": 13.7, "p": 0.29}, {"w": "the", "t0": 13.7, "t1": 13.7, "p": 0.46}, {"w": "judge.", "t0": 13.7, "t1": 13.7, "p": 0.31}], "engine": "faster-whisper/base"}}
A10: 9 | B10: MRG-0467 | C10: audio | D10: en_benign_townhall.wav | E10: audio/wav | F10: 19e41e05058d84b2666886cfba24e5c95288ff94c9ce177d43005c49efdfeb1f | G10: 303404 | H10: 19/19e41e05058d84b2666886cfba24e5c95288ff94c9ce177d43005c49efdfeb1f.wav | I10: 9.48 | J10: {"asr": {"text": "Reminder, the quarterly town hall moves to Friday at 4pm the agenda is in your calendar invite. See you there.", "language": "en", "language_p": 1.0, "words": [{"w": "Reminder,", "t0": 0.0, "t1": 0.78, "p": 0.9}, {"w": "the", "t0": 1.16, "t1": 1.3, "p": 0.91}, {"w": "quarterly", "t0": 1.3, "t1": 1.74, "p": 0.83}, {"w": "town", "t0": 1.74, "t1": 2.06, "p": 0.87}, {"w": "hall", "t0": 2.06, "t1": 2.34, "p": 0.99}, {"w": "moves", "t0": 2.34, "t1": 2.62, "p": 0.98}, {"w": "to", "t0": 2.62, "t1": 2.9, "p": 0.99}, {"w": "Friday", "t0": 2.9, "t1": 3.24, "p": 0.95}, {"w": "at", "t0": 3.24, "t1": 3.64, "p": 0.96}, {"w": "4pm", "t0": 3.64, "t1": 4.3, "p": 0.67}, {"w": "the", "t0": 4.3, "t1": 4.56, "p": 0.6}, {"w": "agenda", "t0": 4.56, "t1": 5.0, "p": 0.96}, {"w": "is", "t0": 5.0, "t1": 5.34, "p": 0.97}, {"w": "in", "t0": 5.34, "t1": 5.48, "p": 1.0}, {"w": "your", "t0": 5.48, "t1": 5.62, "p": 0.99}, {"w": "calendar", "t0": 5.62, "t1": 6.1, "p": 0.97}, {"w": "invite.", "t0": 6.1, "t1": 6.66, "p": 0.94}, {"w": "See", "t0": 7.36, "t1": 8.04, "p": 0.98}, {"w": "you", "t0": 8.04, "t1": 8.2, "p": 0.97}, {"w": "there.", "t0": 8.2, "t1": 8.42, "p": 0.99}], "engine": "faster-whisper/base"}}
A11: 10 | B11: MRG-0468 | C11: audio | D11: spk6930_000.flac | E11: audio/flac | F11: 3f06a2712cadb8d5bca9618a1560112d7e1e0c229e0dd7f0c4f736f4bcb661b3 | G11: 217708 | H11: 3f/3f06a2712cadb8d5bca9618a1560112d7e1e0c229e0dd7f0c4f736f4bcb661b3.flac | I11: 10.81 | J11: {"asr": {"text": "The night was clear, starlet and splendid. The tempest had passed away, and the sweet influences of the evening had restored life, peace and security everywhere.", "language": "en", "language_p": 1.0, "words": [{"w": "The", "t0": 0.0, "t1": 0.4, "p": 0.86}, {"w": "night", "t0": 0.4, "t1": 0.62, "p": 0.98}, {"w": "was", "t0": 0.62, "t1": 0.86, "p": 1.0}, {"w": "clear,", "t0": 0.86, "t1": 1.18, "p": 1.0}, {"w": "starlet", "t0": 1.52, "t1": 1.86, "p": 0.52}, {"w": "and", "t0": 1.86, "t1": 2.18, "p": 0.76}, {"w": "splendid.", "t0": 2.18, "t1": 2.86, "p": 0.93}, {"w": "The", "t0": 3.26, "t1": 3.3, "p": 0.99}, {"w": "tempest", "t0": 3.3, "t1": 3.76, "p": 0.95}, {"w": "had", "t0": 3.76, "t1": 3.92, "p": 0.99}, {"w": "passed", "t0": 3.92, "t1": 4.28, "p": 0.99}, {"w": "away,", "t0": 4.28, "t1": 4.68, "p": 1.0}, {"w": "and", "t0": 4.92, "t1": 4.96, "p": 0.98}, {"w": "the", "t0": 4.96, "t1": 5.1, "p": 1.0}, {"w": "sweet", "t0": 5.1, "t1": 5.46, "p": 0.99}, {"w": "influences", "t0": 5.46, "t1": 6.14, "p": 0.99}, {"w": "of", "t0": 6.14, "t1": 6.44, "p": 1.0}, {"w": "the", "t0": 6.44, "t1": 6.64, "p": 0.99}, {"w": "evening", "t0": 6.64, "t1": 6.94, "p": 1.0}, {"w": "had", "t0": 6.94, "t1": 7.18, "p": 0.97}, {"w": "restored", "t0": 7.18, "t1": 7.64, "p": 0.99}, {"w": "life,", "t0": 7.64, "t1": 8.26, "p": 0.99}, {"w": "peace", "t0": 8.78, "t1": 8.9, "p": 1.0}, {"w": "and", "t0": 8.9, "t1": 9.18, "p": 0.56}, {"w": "security", "t0": 9.18, "t1": 9.72, "p": 1.0}, {"w": "everywhere.", "t0": 9.72, "t1": 10.36, "p": 0.95}], "engine": "faster-whisper/base"}}
A12: 11 | B12: MRG-0469 | C12: audio | D12: spk6930_000.flac | E12: audio/flac | F12: 3f06a2712cadb8d5bca9618a1560112d7e1e0c229e0dd7f0c4f736f4bcb661b3 | G12: 217708 | H12: 3f/3f06a2712cadb8d5bca9618a1560112d7e1e0c229e0dd7f0c4f736f4bcb661b3.flac | I12: 10.81 | J12: {"asr": {"text": "The night was clear, starlet and splendid. The tempest had passed away, and the sweet influences of the evening had restored life, peace and security everywhere.", "language": "en", "language_p": 1.0, "words": [{"w": "The", "t0": 0.0, "t1": 0.4, "p": 0.86}, {"w": "night", "t0": 0.4, "t1": 0.62, "p": 0.98}, {"w": "was", "t0": 0.62, "t1": 0.86, "p": 1.0}, {"w": "clear,", "t0": 0.86, "t1": 1.18, "p": 1.0}, {"w": "starlet", "t0": 1.52, "t1": 1.86, "p": 0.52}, {"w": "and", "t0": 1.86, "t1": 2.18, "p": 0.76}, {"w": "splendid.", "t0": 2.18, "t1": 2.86, "p": 0.93}, {"w": "The", "t0": 3.26, "t1": 3.3, "p": 0.99}, {"w": "tempest", "t0": 3.3, "t1": 3.76, "p": 0.95}, {"w": "had", "t0": 3.76, "t1": 3.92, "p": 0.99}, {"w": "passed", "t0": 3.92, "t1": 4.28, "p": 0.99}, {"w": "away,", "t0": 4.28, "t1": 4.68, "p": 1.0}, {"w": "and", "t0": 4.92, "t1": 4.96, "p": 0.98}, {"w": "the", "t0": 4.96, "t1": 5.1, "p": 1.0}, {"w": "sweet", "t0": 5.1, "t1": 5.46, "p": 0.99}, {"w": "influences", "t0": 5.46, "t1": 6.14, "p": 0.99}, {"w": "of", "t0": 6.14, "t1": 6.44, "p": 1.0}, {"w": "the", "t0": 6.44, "t1": 6.64, "p": 0.99}, {"w": "evening", "t0": 6.64, "t1": 6.94, "p": 1.0}, {"w": "had", "t0": 6.94, "t1": 7.18, "p": 0.97}, {"w": "restored", "t0": 7.18, "t1": 7.64, "p": 0.99}, {"w": "life,", "t0": 7.64, "t1": 8.26, "p": 0.99}, {"w": "peace", "t0": 8.78, "t1": 8.9, "p": 1.0}, {"w": "and", "t0": 8.9, "t1": 9.18, "p": 0.56}, {"w": "security", "t0": 9.18, "t1": 9.72, "p": 1.0}, {"w": "everywhere.", "t0": 9.72, "t1": 10.36, "p": 0.95}], "engine": "faster-whisper/base"}}
A13: 12 | B13: MRG-0470 | C13: image | D13: 02.png | E13: image/png | F13: ecd406882d7865d068ce1df66d8661c7e8943be2e2205fce1f43bd277e7f8199 | G13: 380588 | H13: ec/ecd406882d7865d068ce1df66d8661c7e8943be2e2205fce1f43bd277e7f8199.png | J13: {"ocr": {"text": "MIRAGE RED TEAM\u00b7SYNTHETIC", "lines": [{"text": "MIRAGE RED TEAM\u00b7SYNTHETIC", "conf": 0.96, "box": [0.6875, 0.9668, 0.3027, 0.0312]}], "engine": "rapidocr"}}
A14: 13 | B14: MRG-0471 | C14: image | D14: 000.jpg | E14: image/jpeg | F14: fe553ba0662dcbb1a66e8aabcbd421831bb3f31536ab89ff8c464a3fd59387c6 | G14: 22901 | H14: fe/fe553ba0662dcbb1a66e8aabcbd421831bb3f31536ab89ff8c464a3fd59387c6.jpg | J14: {}
A15: 14 | B15: MRG-0477 | C15: audio | D15: ta_otp.wav | E15: audio/wav | F15: 0e30f0bdfc206f4787d0a4ec69f695f50db7d3f57c858dbb876fbc1507e1fb45 | G15: 330284 | H15: 0e/0e30f0bdfc206f4787d0a4ec69f695f50db7d3f57c858dbb876fbc1507e1fb45.wav | I15: 10.32 | J15: {"asr": {"text": "\u0bb5\u0ba3\u0b95\u0bcd\u0b95\u0bae\u0bcd \u0ba8\u0bbe\u0ba9\u0bcd \u0bb5\u0ba3\u0bcd\u0b95\u0bbf\u0baf\u0bbf\u0bb2\u0bbf\u0bb0\u0bc1\u0ba8\u0bcd\u0ba4\u0bc1 \u0baa\u0bc7\u0b9a\u0bc1\u0b95\u0bbf\u0bb1\u0bc7\u0ba9\u0bcd \u0b89\u0b99\u0bcd\u0b95\u0bb3\u0bcd \u0b95\u0ba3\u0b95\u0bcd\u0b95\u0bc1 \u0b8e\u0ba9\u0bcd\u0bb1\u0bc1 \u0bae\u0bc1\u0b9f\u0b95\u0bcd\u0b95\u0baa\u0bcd\u0baa\u0b9f\u0bc1\u0bae\u0bcd \u0b89\u0b99\u0bcd\u0b95\u0bb3\u0bcd \u0bae\u0bc1\u0baa\u0bcd\u0baa\u0bc8\u0baf\u0bbf\u0bb2\u0bcd \u0b95\u0bc1 \u0bb5\u0ba8\u0bcd\u0ba4\u0bc1 OTP -NNI \u0b89\u0b9f\u0ba9\u0bc7 \u0b9a\u0bca\u0bb2\u0bcd\u0bb2\u0b99\u0bcd\u0b95\u0bb3\u0bcd", "language": "ta", "language_p": 1.0, "words": [{"w": "\u0bb5\u0ba3\u0b95\u0bcd\u0b95\u0bae\u0bcd", "t0": 0.0, "t1": 0.9, "p": 0.8}, {"w": "\u0ba8\u0bbe\u0ba9\u0bcd", "t0": 0.9, "t1": 1.4, "p": 0.83}, {"w": "\u0bb5\u0ba3\u0bcd\u0b95\u0bbf\u0baf\u0bbf\u0bb2\u0bbf\u0bb0\u0bc1\u0ba8\u0bcd\u0ba4\u0bc1", "t0": 1.4, "t1": 2.18, "p": 0.73}, {"w": "\u0baa\u0bc7\u0b9a\u0bc1\u0b95\u0bbf\u0bb1\u0bc7\u0ba9\u0bcd", "t0": 2.18, "t1": 3.0, "p": 0.81}, {"w": "\u0b89\u0b99\u0bcd\u0b95\u0bb3\u0bcd", "t0": 3.8, "t1": 4.2, "p": 0.92}, {"w": "\u0b95\u0ba3\u0b95\u0bcd\u0b95\u0bc1", "t0": 4.2, "t1": 4.58, "p": 0.89}, {"w": "\u0b8e\u0ba9\u0bcd\u0bb1\u0bc1", "t0": 4.58, "t1": 4.94, "p": 0.76}, {"w": "\u0bae\u0bc1\u0b9f\u0b95\u0bcd\u0b95\u0baa\u0bcd\u0baa\u0b9f\u0bc1\u0bae\u0bcd", "t0": 4.94, "t1": 6.3, "p": 0.78}, {"w": "\u0b89\u0b99\u0bcd\u0b95\u0bb3\u0bcd", "t0": 6.3, "t1": 7.14, "p": 0.99}, {"w": "\u0bae\u0bc1\u0baa\u0bcd\u0baa\u0bc8\u0baf\u0bbf\u0bb2\u0bcd", "t0": 7.14, "t1": 7.56, "p": 0.7}, {"w": "\u0b95\u0bc1", "t0": 7.56, "t1": 7.72, "p": 0.35}, {"w": "\u0bb5\u0ba8\u0bcd\u0ba4\u0bc1", "t0": 7.72, "t1": 8.18, "p": 0.74}, {"w": "OTP", "t0": 8.18, "t1": 8.6, "p": 0.51}, {"w": "-NNI", "t0": 8.6, "t1": 9.12, "p": 0.48}, {"w": "\u0b89\u0b9f\u0ba9\u0bc7", "t0": 9.12, "t1": 9.54, "p": 0.7}, {"w": "\u0b9a\u0bca\u0bb2\u0bcd\u0bb2\u0b99\u0bcd\u0b …(truncated)
A16: 15 | B16: MRG-0478 | C16: audio | D16: google_tamil_m_spk3191_002__noise.wav | E16: audio/wav | F16: 90db5ae7d9061875784f6361967a0f31023fdb9b0c5e15c1e72bd6e964ccae17 | G16: 155692 | H16: 90/90db5ae7d9061875784f6361967a0f31023fdb9b0c5e15c1e72bd6e964ccae17.wav | I16: 4.86 | J16: {"asr": {"text": "\u0ba8\u0bcb\u0b95\u0bcd\u0b95\u0bbf\u0baf\u0bbe \u0bae\u0bc8\u0b95\u0bcd\u0b95\u0bb0\u0b9a\u0bcd \u0b9a\u0bbe\u0baa\u0bcd\u0b9f\u0bc1\u0b9f\u0ba9\u0bcd \u0b8e\u0ba9\u0bcd\u0ba9 \u0b87\u0ba8\u0bcd\u0ba4 \u0b9a\u0bc6\u0baf\u0bcd\u0baf\u0bb2\u0bcd \u0baa\u0b9f \u0bae\u0bc1\u0b9f\u0bbf\u0bb5\u0bc7", "language": "ta", "language_p": 1.0, "words": [{"w": "\u0ba8\u0bcb\u0b95\u0bcd\u0b95\u0bbf\u0baf\u0bbe", "t0": 0.4, "t1": 1.2, "p": 0.61}, {"w": "\u0bae\u0bc8\u0b95\u0bcd\u0b95\u0bb0\u0b9a\u0bcd", "t0": 1.2, "t1": 1.68, "p": 0.51}, {"w": "\u0b9a\u0bbe\u0baa\u0bcd\u0b9f\u0bc1\u0b9f\u0ba9\u0bcd", "t0": 1.68, "t1": 2.32, "p": 0.74}, {"w": "\u0b8e\u0ba9\u0bcd\u0ba9", "t0": 2.32, "t1": 2.48, "p": 0.79}, {"w": "\u0b87\u0ba8\u0bcd\u0ba4", "t0": 2.48, "t1": 2.68, "p": 0.88}, {"w": "\u0b9a\u0bc6\u0baf\u0bcd\u0baf\u0bb2\u0bcd", "t0": 2.68, "t1": 3.24, "p": 0.71}, {"w": "\u0baa\u0b9f", "t0": 3.24, "t1": 3.32, "p": 0.7}, {"w": "\u0bae\u0bc1\u0b9f\u0bbf\u0bb5\u0bc7", "t0": 3.32, "t1": 3.72, "p": 0.79}], "engine": "faster-whisper/base"}}
A17: 16 | B17: MRG-0479 | C17: image | D17: 07_whatsapp_cfo_chat_screenshot.png | E17: image/png | F17: 9352f46f9ef1860dd9fd6bb00b7654c4682122a1663ac24c0671aae1d90d1d41 | G17: 42090 | H17: 93/9352f46f9ef1860dd9fd6bb00b7654c4682122a1663ac24c0671aae1d90d1d41.png | J17: {"ocr": {"text": "Rajesh Mehta (CFO)\nonline\nHi Kavita, Rajesh here. In a board meeting,\ncan't talk.\nPlease process Rs 9,80,000 to Orbit\nSupplies'new account 600112233445 IFSC\nHDFC0001234 today.\nSure, should I loop in audit?\nNo,keep this between us until the audit\ncloses.Very urgent,before 4 PM.", "lines": [{"text": "Rajesh Mehta (CFO)", "conf": 0.99, "box": [0.0944, 0.0294, 0.2875, 0.0496]}, {"text": "online", "conf": 0.99, "box": [0.0944, 0.0882, 0.0708, 0.0349]}, {"text": "Hi Kavita, Rajesh here. In a board meeting,", "conf": 0.96, "box": [0.0431, 0.204, 0.5875, 0.0496]}, {"text": "can't talk.", "conf": 0.95, "box": [0.0444, 0.2629, 0.1278, 0.0404]}, {"text": "Please process Rs 9,80,000 to Orbit", "conf": 0.97, "box": [0.0458, 0.3824, 0.4931, 0.0423]}, {"text": "Supplies'new account 600112233445 IFSC", "conf": 0.97, "box": [0.0444, 0.4357, 0.5944, 0.046]}, {"text": "HDFC0001234 today.", "conf": 0.99, "box": [0.0431, 0.4871, 0.2972, 0.0533]}, {"text": "Sure, should I loop in audit?", "conf": 0.97, "box": [0.5764, 0.6158, 0.3778, 0.0404]}, {"text": "No,keep this between us until the audit", "conf": 0.96, "box": [0.0431, 0.7353, 0.5403, 0.0423]}, {"text": "closes.Very urgent,before 4 PM.", "conf": 0.99, "box": [0.0458, 0.7941, 0.4514, 0.0386]}], "engine": "rapidocr"}}
A18: 17 | B18: MRG-0480 | C18: text | D18: 01_vendor_bank_change_bec.eml | E18: text/plain | F18: f8a7017d25072502f6e6cf4390b82f690ceaf4c6fac0c321f87dbf16a6856e79 | G18: 960 | H18: f8/f8a7017d25072502f6e6cf4390b82f690ceaf4c6fac0c321f87dbf16a6856e79.eml | J18: {}
A19: 18 | B19: MRG-0481 | C19: text | D19: 02_ceo_gift_cards_urgent.eml | E19: text/plain | F19: 51354c917e32e3aa256912f89bf4f26f08760b04a60e3b776318ec14c07b6b94 | G19: 575 | H19: 51/51354c917e32e3aa256912f89bf4f26f08760b04a60e3b776318ec14c07b6b94.eml | J19: {}
A20: 19 | B20: MRG-0482 | C20: text | D20: 03_password_expiry_phishing.eml | E20: text/plain | F20: 02c67d1cd12ff0680714a89d74039101e5632a15e1e8418e3a639c49761225b1 | G20: 551 | H20: 02/02c67d1cd12ff0680714a89d74039101e5632a15e1e8418e3a639c49761225b1.eml | J20: {}
A21: 20 | B21: MRG-0483 | C21: text | D21: 04_benign_hr_newsletter.eml | E21: text/plain | F21: 4bf350238f37abd18e43521f591d257eea2ddb62e0c6a970acfce20f6ee7d262 | G21: 452 | H21: 4b/4bf350238f37abd18e43521f591d257eea2ddb62e0c6a970acfce20f6ee7d262.eml | J21: {}
A22: 21 | B22: MRG-0484 | C22: audio | D22: cfo_voice_note.ogg | E22: audio/ogg | F22: 76804f5c9ce590d9736b14708da395f59772b54da34102673c29f621cbcedcbd | G22: 45575 | H22: 76/76804f5c9ce590d9736b14708da395f59772b54da34102673c29f621cbcedcbd.ogg | I22: 17.62 | J22: {"asr": {"text": "Hi, it's Rajesh from the CFO office. I'm in a board meeting and can't take calls. Please wire 48 lakh rupees to the new vendor account before 4 pm it's urgent and confidential. Don't loop in audit.", "language": "en", "language_p": 1.0, "words": [{"w": "Hi,", "t0": 0.0, "t1": 0.38, "p": 0.9}, {"w": "it's", "t0": 0.72, "t1": 1.16, "p": 0.69}, {"w": "Rajesh", "t0": 1.16, "t1": 1.5, "p": 0.98}, {"w": "from", "t0": 1.5, "t1": 1.78, "p": 0.99}, {"w": "the", "t0": 1.78, "t1": 1.98, "p": 0.97}, {"w": "CFO", "t0": 1.98, "t1": 2.4, "p": 0.85}, {"w": "office.", "t0": 2.4, "t1": 3.0, "p": 0.75}, {"w": "I'm", "t0": 3.7, "t1": 4.24, "p": 0.9}, {"w": "in", "t0": 4.24, "t1": 4.38, "p": 0.99}, {"w": "a", "t0": 4.38, "t1": 4.5, "p": 0.97}, {"w": "board", "t0": 4.5, "t1": 4.76, "p": 0.92}, {"w": "meeting", "t0": 4.76, "t1": 5.22, "p": 1.0}, {"w": "and", "t0": 5.22, "t1": 5.78, "p": 0.87}, {"w": "can't", "t0": 5.78, "t1": 6.18, "p": 0.96}, {"w": "take", "t0": 6.18, "t1": 6.44, "p": 1.0}, {"w": "calls.", "t0": 6.44, "t1": 6.84, "p": 0.97}, {"w": "Please", "t0": 7.86, "t1": 8.12, "p": 0.98}, {"w": "wire", "t0": 8.12, "t1": 8.52, "p": 0.87}, {"w": "48", "t0": 8.52, "t1": 9.34, "p": 0.94}, {"w": "lakh", "t0": 9.34, "t1": 9.7, "p": 0.31}, {"w": "rupees", "t0": 9.7, "t1": 10.14, "p": 0.89}, {"w": "to", "t0": 10.14, "t1": 10.48, "p": 0.99}, {"w": "the", "t0": 10.48, "t1": 10.62, "p": 0.99}, {"w": "new", "t0": 10.62, "t1": 10.84, "p": 0.85}, {"w": "vendor", "t0": 10.84, "t1": 11.18, "p": 0.81}, {"w": "account", "t0": 11.18, "t1": 11.66, "p": 0.99}, {"w": "before", "t0": 11.66, "t1": 12.16, "p": 0.92}, {"w": "4", "t0": 12.16, "t1": 12.7, "p": 0.98}, {"w": "pm", "t0": 12.7, "t1": 13.02, "p": 0.33}, {"w": "it's", "t0": 13.02, "t1": 13.54, "p": 0.68}, {"w": "urgent", "t0": 13.54, "t1": 13.86, "p": 0.98}, {"w": "and", "t0": 13.86, "t1": 14.26, "p": 0.98}, {"w": "confidential.", "t0": 14.26, "t1": 14.94, "p": 1.0}, {"w": "Don't", "t0": 15.42, "t1": 15.72, "p": 0.93}, {"w": "loop", …(truncated)
A23: 22 | B23: MRG-0485 | C23: video | D23: video_call.mp4 | E23: video/mp4 | F23: c82097dc6a47d2309350a516a095c5a8eb99a548c9001f7dcf3bc26eff30d2d0 | G23: 378965 | H23: c8/c82097dc6a47d2309350a516a095c5a8eb99a548c9001f7dcf3bc26eff30d2d0.mp4 | I23: 23.1 | J23: {"asr": {"text": "This is Inspector Sharma from the CBI CyberSair. A parcel in your name has illegal items and an arrest warrant is issued. Stay on this video call and do not disconnect. Transfer your savings to the RBI verification account to avoid arrest. Do not tell anyone.", "language": "en", "language_p": 1.0, "words": [{"w": "This", "t0": 0.0, "t1": 0.4, "p": 0.93}, {"w": "is", "t0": 0.4, "t1": 0.7, "p": 0.99}, {"w": "Inspector", "t0": 0.7, "t1": 1.34, "p": 0.87}, {"w": "Sharma", "t0": 1.34, "t1": 1.84, "p": 0.97}, {"w": "from", "t0": 1.84, "t1": 2.14, "p": 0.98}, {"w": "the", "t0": 2.14, "t1": 2.3, "p": 0.93}, {"w": "CBI", "t0": 2.3, "t1": 2.84, "p": 0.75}, {"w": "CyberSair.", "t0": 2.84, "t1": 3.7, "p": 0.23}, {"w": "A", "t0": 4.36, "t1": 4.92, "p": 0.82}, {"w": "parcel", "t0": 4.92, "t1": 5.2, "p": 0.98}, {"w": "in", "t0": 5.2, "t1": 5.56, "p": 0.98}, {"w": "your", "t0": 5.56, "t1": 5.8, "p": 0.99}, {"w": "name", "t0": 5.8, "t1": 6.14, "p": 0.97}, {"w": "has", "t0": 6.14, "t1": 6.62, "p": 0.99}, {"w": "illegal", "t0": 6.62, "t1": 7.02, "p": 0.98}, {"w": "items", "t0": 7.02, "t1": 7.54, "p": 0.98}, {"w": "and", "t0": 7.54, "t1": 8.1, "p": 0.79}, {"w": "an", "t0": 8.1, "t1": 8.36, "p": 0.85}, {"w": "arrest", "t0": 8.36, "t1": 8.56, "p": 0.99}, {"w": "warrant", "t0": 8.56, "t1": 9.04, "p": 1.0}, {"w": "is", "t0": 9.04, "t1": 9.38, "p": 0.96}, {"w": "issued.", "t0": 9.38, "t1": 9.72, "p": 0.99}, {"w": "Stay", "t0": 10.34, "t1": 11.06, "p": 0.97}, {"w": "on", "t0": 11.06, "t1": 11.36, "p": 1.0}, {"w": "this", "t0": 11.36, "t1": 11.68, "p": 0.99}, {"w": "video", "t0": 11.68, "t1": 12.06, "p": 0.98}, {"w": "call", "t0": 12.06, "t1": 12.38, "p": 0.93}, {"w": "and", "t0": 12.38, "t1": 12.9, "p": 0.93}, {"w": "do", "t0": 12.9, "t1": 13.08, "p": 0.97}, {"w": "not", "t0": 13.08, "t1": 13.32, "p": 0.99}, {"w": "disconnect.", "t0": 13.32, "t1": 13.92, "p": 1.0}, {"w": "Transfer", "t0": 14.86, "t1": 15.48, "p": 0.98}, {"w": "your", "t0": 15.48, "t1": 15.82, "p": 0.99}, {" …(truncated)
A24: 23 | B24: MRG-0486 | C24: audio | D24: papa_voice.ogg | E24: audio/ogg | F24: 5bc20c8a106e85862e3a8d71c9ba55d57d863e6ab5d75e170636c2243ddd4e23 | G24: 38664 | H24: 5b/5bc20c8a106e85862e3a8d71c9ba55d57d863e6ab5d75e170636c2243ddd4e23.ogg | I24: 16.99 | J24: {"asr": {"text": "Papa, I am. Accident is over and phone is broken. This is the number of friends.", "language": "hi-Latn (Hinglish)", "language_p": 1.0, "words": [{"w": "Papa,", "t0": 0.0, "t1": 0.58, "p": 0.37}, {"w": "I", "t0": 0.9, "t1": 1.3, "p": 0.89}, {"w": "am.", "t0": 1.3, "t1": 1.6, "p": 0.79}, {"w": "Accident", "t0": 2.62, "t1": 3.26, "p": 0.58}, {"w": "is", "t0": 3.26, "t1": 3.52, "p": 0.65}, {"w": "over", "t0": 3.52, "t1": 3.72, "p": 0.08}, {"w": "and", "t0": 3.72, "t1": 4.22, "p": 0.69}, {"w": "phone", "t0": 4.22, "t1": 4.54, "p": 0.23}, {"w": "is", "t0": 4.54, "t1": 4.8, "p": 0.7}, {"w": "broken.", "t0": 4.8, "t1": 4.96, "p": 0.62}, {"w": "This", "t0": 5.44, "t1": 5.72, "p": 0.69}, {"w": "is", "t0": 5.72, "t1": 6.14, "p": 0.93}, {"w": "the", "t0": 6.14, "t1": 6.3, "p": 0.66}, {"w": "number", "t0": 6.3, "t1": 6.62, "p": 0.67}, {"w": "of", "t0": 6.62, "t1": 6.78, "p": 0.95}, {"w": "friends.", "t0": 6.78, "t1": 6.78, "p": 0.75}], "engine": "faster-whisper/base"}}
A25: 24 | B25: MRG-0487 | C25: image | D25: accounts_manager.jpg | E25: image/jpeg | F25: 044c58a1e2a77eb23602a272ef458789c1e9fe7ff494c7a7adb14ec045624187 | G25: 71244 | H25: 04/044c58a1e2a77eb23602a272ef458789c1e9fe7ff494c7a7adb14ec045624187.jpg | J25: {"ocr": {"text": "MIRAGE RED TEAM\u00b7SYNTHETIC", "lines": [{"text": "MIRAGE RED TEAM\u00b7SYNTHETIC", "conf": 0.98, "box": [0.6914, 0.9688, 0.2969, 0.0273]}], "engine": "rapidocr"}}
A26: 25 | B26: MRG-0487 | C26: text | D26: invoice.eml | E26: text/plain | F26: f8a7017d25072502f6e6cf4390b82f690ceaf4c6fac0c321f87dbf16a6856e79 | G26: 960 | H26: f8/f8a7017d25072502f6e6cf4390b82f690ceaf4c6fac0c321f87dbf16a6856e79.eml | J26: {}
A27: 26 | B27: MRG-0488 | C27: audio | D27: townhall.mp3 | E27: audio/mpeg | F27: e6d8bbfd37a6f671ac1887cebe8cbbb9a77ceb30a0ba791a8c625227c1610534 | G27: 97100 | H27: e6/e6d8bbfd37a6f671ac1887cebe8cbbb9a77ceb30a0ba791a8c625227c1610534.mp3 | I27: 12 | J27: {"asr": {"text": "Good morning team. The quarterly town hall moves to Friday at 4pm in the main auditorium. Snacks will be served. See you there.", "language": "en", "language_p": 1.0, "words": [{"w": "Good", "t0": 0.0, "t1": 0.4, "p": 0.84}, {"w": "morning", "t0": 0.4, "t1": 0.78, "p": 0.81}, {"w": "team.", "t0": 0.78, "t1": 1.26, "p": 0.75}, {"w": "The", "t0": 2.28, "t1": 2.4, "p": 0.98}, {"w": "quarterly", "t0": 2.4, "t1": 2.86, "p": 0.68}, {"w": "town", "t0": 2.86, "t1": 3.18, "p": 0.89}, {"w": "hall", "t0": 3.18, "t1": 3.48, "p": 0.98}, {"w": "moves", "t0": 3.48, "t1": 3.78, "p": 0.99}, {"w": "to", "t0": 3.78, "t1": 4.04, "p": 0.99}, {"w": "Friday", "t0": 4.04, "t1": 4.36, "p": 0.93}, {"w": "at", "t0": 4.36, "t1": 4.74, "p": 0.98}, {"w": "4pm", "t0": 4.74, "t1": 5.38, "p": 0.66}, {"w": "in", "t0": 5.38, "t1": 5.7, "p": 0.97}, {"w": "the", "t0": 5.7, "t1": 5.8, "p": 0.97}, {"w": "main", "t0": 5.8, "t1": 6.12, "p": 0.95}, {"w": "auditorium.", "t0": 6.12, "t1": 6.92, "p": 1.0}, {"w": "Snacks", "t0": 7.92, "t1": 8.4, "p": 0.95}, {"w": "will", "t0": 8.4, "t1": 8.62, "p": 1.0}, {"w": "be", "t0": 8.62, "t1": 8.8, "p": 1.0}, {"w": "served.", "t0": 8.8, "t1": 9.18, "p": 0.99}, {"w": "See", "t0": 10.02, "t1": 10.54, "p": 0.99}, {"w": "you", "t0": 10.54, "t1": 10.7, "p": 0.99}, {"w": "there.", "t0": 10.7, "t1": 10.96, "p": 0.99}], "engine": "faster-whisper/base"}}
